<?xml version="1.0" ?>
<!-- =================================================================================== -->
<!-- |    This document was autogenerated by xacro from robotarm_5DOF.xacro            | -->
<!-- |    EDITING THIS FILE BY HAND IS NOT RECOMMENDED                                 | -->
<!-- =================================================================================== -->
<!-- Revolute-Revolute Manipulator -->
<robot name="robotarm_5DOF" xmlns:xacro="http://www.ros.org/wiki/xacro">
  <!-- ros_control plugin -->
  <gazebo>
    <plugin filename="libgazebo_ros_control.so" name="gazebo_ros_control">
      <robotNamespace>/robotarm_5DOF</robotNamespace>
      <robotSimType>gazebo_ros_control/DefaultRobotHWSim</robotSimType>
    </plugin>
  </gazebo>
  <!-- World -->
  <gazebo reference="world">
  </gazebo>
  <!-- base_link -->
  <gazebo reference="base_link">
    <mu1>0.2</mu1>
    <mu2>0.2</mu2>
    <material>Gazebo/Grey</material>
  </gazebo>
  <!-- Link1 -->
  <gazebo reference="link1">
    <mu1>0.2</mu1>
    <mu2>0.2</mu2>
    <material>Gazebo/Grey</material>
  </gazebo>
  <!-- Link2 -->
  <gazebo reference="link2">
    <mu1>0.2</mu1>
    <mu2>0.2</mu2>
    <material>Gazebo/Grey</material>
  </gazebo>
  <!-- Link3 -->
  <gazebo reference="link3">
    <mu1>0.2</mu1>
    <mu2>0.2</mu2>
    <material>Gazebo/Grey</material>
  </gazebo>
  <!-- Link4 -->
  <gazebo reference="link4">
    <mu1>0.2</mu1>
    <mu2>0.2</mu2>
    <material>Gazebo/Grey</material>
  </gazebo>
  <!-- link_end -->
  <gazebo reference="link_end">
    <mu1>0.2</mu1>
    <mu2>0.2</mu2>
    <material>Gazebo/Grey</material>
  </gazebo>
  <!-- ros_control plugin deleted stuff from here but on top should be the same -->
  <!-- Used for fixing robot to Gazebo 'base_link' -->
  <link name="world">
  </link>
  <joint name="world" type="fixed">
    <origin rpy="0 0 0" xyz="0 0 0.13"/>
    <parent link="world"/>
    <child link="base_link"/>
  </joint>
  <link name="base_link">
    <inertial>
      <origin rpy="0 0 0" xyz="0 0 0"/>
      <mass value="0.854996764620972"/>
      <inertia ixx="0.00127367657233133" ixy="-9.78923195537527E-13" ixz="-2.93635909372344E-13" iyy="0.00127209146192002" iyz="1.73326120869336E-07" izz="0.000375253307095422"/>
    </inertial>
    <visual>
      <origin rpy="0 0 0" xyz="0 0 0"/>
      <geometry>
        <mesh filename="package://manipulator_h_description/meshes_5DOF/base_link.STL"/>
      </geometry>
      <material name="">
        <color rgba="0.792156862745098 0.819607843137255 0.929411764705882 1"/>
      </material>
    </visual>
    <collision>
      <origin rpy="0 0 0" xyz="0 0 0"/>
      <geometry>
        <mesh filename="package://manipulator_h_description/meshes_5DOF/base_link.STL"/>
      </geometry>
    </collision>
  </link>
  <joint name="joint1" type="revolute">
    <origin rpy="0 0 0" xyz="0 0 0.075"/>
    <parent link="base_link"/>
    <child link="link1"/>
    <limit effort="1000" lower="-3.14" upper="3.14" velocity="6.5"/>
    <dynamics damping="1"/>
    <axis xyz="0 0 1"/>
  </joint>

  <link name="link1">
    <inertial>
      <origin rpy="3.14 0 0" xyz="0 0 -0.039"/>
      <mass value="0.933973833115025"/>
      <inertia ixx="0.00130038494228848" ixy="-2.95844372439728E-13" ixz="-3.01467763831998E-11" iyy="0.000422142499355785" iyz="-1.73339894386112E-07" izz="0.0013123580996147"/>
    </inertial>
    <visual>
      <origin rpy="3.14 0 0" xyz="0 0 -0.039"/>
      <geometry>
        <mesh filename="package://manipulator_h_description/meshes_5DOF/link1.STL"/>
      </geometry>
      <material name="">
        <color rgba="0.752941176470588 0.752941176470588 0.752941176470588 1"/>
      </material>
    </visual>
    <collision>
      <origin rpy="3.14 0 0" xyz="0 0 -0.039"/>
      <geometry>
        <mesh filename="package://manipulator_h_description/meshes_5DOF/link1.STL"/>
      </geometry>
    </collision>
  </link>
  <joint name="joint2" type="revolute">
    <origin rpy="1.57 0 0" xyz="0 0 -0.04"/>
    <parent link="link1"/>
    <child link="link2"/>
    <axis xyz="0 0 1"/>
    <limit effort="1000" lower="-3.14" upper="3.14" velocity="6.5"/>
    <dynamics damping="1"/>
  </joint>

  <link name="link2">
    <inertial>
      <origin rpy="0 0 0" xyz="0 0 0"/>
      <mass value="2.17233482675649"/>
      <inertia ixx="0.012588710454961" ixy="3.24699537352499E-11" ixz="-1.73376873509498E-07" iyy="0.00229782223136213" iyz="-2.39564649019806E-07" izz="0.0112510434237469"/>
    </inertial>
    <visual>
      <origin rpy="0 0 0" xyz="0 0 0"/>
      <geometry>
        <mesh filename="package://manipulator_h_description/meshes_5DOF/link2.STL"/>
      </geometry>
      <material name="">
        <color rgba="0.752941176470588 0.752941176470588 0.752941176470588 1"/>
      </material>
    </visual>
    <collision>
      <origin rpy="0 0 0" xyz="0 0 0"/>
      <geometry>
        <mesh filename="package://manipulator_h_description/meshes_5DOF/link2.STL"/>
      </geometry>
    </collision>
  </link>
  <joint name="joint3" type="revolute">
    <origin rpy="0 0 0" xyz="0 0.548 0"/>
    <parent link="link2"/>
    <child link="link3"/>
    <axis xyz="0 0 1"/>
    <limit effort="1000" lower="-3.14" upper="3.14" velocity="6.5"/>
    <dynamics damping="1"/>
  </joint>

  <link name="link3">
    <inertial>
      <origin rpy="0 0 0" xyz="0 0 0"/>
      <mass value="2.03963402194097"/>
      <inertia ixx="0.0121595677954515" ixy="1.8895677510483E-12" ixz="1.26403080065892E-07" iyy="0.00186854119614137" iyz="-2.39564391781716E-07" izz="0.011185917848878"/>
    </inertial>
    <visual>
      <origin rpy="0 0 0" xyz="0 0 0"/>
      <geometry>
        <mesh filename="package://manipulator_h_description/meshes_5DOF/link3.STL"/>
      </geometry>
      <material name="">
        <color rgba="0.752941176470588 0.752941176470588 0.752941176470588 1"/>
      </material>
    </visual>
    <collision>
      <origin rpy="0 0 0" xyz="0 0 0"/>
      <geometry>
        <mesh filename="package://manipulator_h_description/meshes_5DOF/link3.STL"/>
      </geometry>
    </collision>
  </link>
  <joint name="joint4" type="revolute">
    <origin rpy="0 0 0" xyz="0 0.548 0"/>
    <parent link="link3"/>
    <child link="link4"/>
    <axis xyz="0 0 1"/>
    <limit effort="1000" lower="-3.14" upper="3.14" velocity="6.5"/>
    <dynamics damping="0.7"/>
  </joint>

  <link name="link4">
    <inertial>
      <origin rpy="0 0 0" xyz="-5.84108303602587E-11 0.093757042570968 0.000563667312071903"/>
      <mass value="0.86104149872866"/>
      <inertia ixx="1.0" ixy="0.0" ixz="0.0" iyy="1.0" iyz="0.0" izz="1.0"/>
      <!---inertia
        ixx="0.000958719090443109"
        ixy="-6.78889479385674E-14"
        ixz="-1.92825748989735E-12"
        iyy="0.000454069680151404"
        iyz="-2.64915719473377E-07"
        izz="0.000905174777740181" /-->
    </inertial>
    <visual>
      <origin rpy="0 0 0" xyz="0 0 0"/>
      <geometry>
        <mesh filename="package://manipulator_h_description/meshes_5DOF/link4.STL"/>
      </geometry>
      <material name="">
        <color rgba="0.752941176470588 0.752941176470588 0.752941176470588 1"/>
      </material>
    </visual>
    <collision>
      <origin rpy="0 0 0" xyz="0 0 0"/>
      <geometry>
        <mesh filename="package://manipulator_h_description/meshes_5DOF/link4.STL"/>
      </geometry>
    </collision>
  </link>
  <joint name="joint5" type="revolute">
    <origin rpy="0 0 0" xyz="0 0.159 0"/>
    <parent link="link4"/>
    <child link="end"/>
    <axis xyz="0 1 0"/>
    <limit effort="1000" lower="-3.14" upper="3.14" velocity="6.5"/>
    <dynamics damping="0.7"/>
  </joint>

  <link name="end">
    <inertial>
      <origin rpy="0 0 0" xyz="0 0.03 0"/>
      <mass value="0.01"/>
      <inertia ixx="1.0" ixy="0.0" ixz="0.0" iyy="1.0" iyz="0.0" izz="1.0"/>
      <!--inertia
        ixx="0.000259199999999999"
        ixy="5.34084614707402E-19"
        ixz="-9.20138409382816E-20"
        iyy="0.000648"
        iyz="4.45440999867654E-20"
        izz="0.000647999999999999" /-->
    </inertial>
    <visual>
      <origin rpy="0 0 0" xyz="0 0.06 0"/>
      <geometry>
        <mesh filename="package://manipulator_h_description/meshes_5DOF/end.STL"/>
      </geometry>
      <material name="">
        <color rgba="0.792156862745098 0.819607843137255 0.933333333333333 1"/>
      </material>
    </visual>
    <collision>
      <origin rpy="0 0 0" xyz="0 0.06 0"/>
      <geometry>
        <mesh filename="package://manipulator_h_description/meshes_5DOF/end.STL"/>
      </geometry>
    </collision>
  </link>
  
  <gazebo>
    <plugin filename="libgazebo_ros_control.so" name="gazebo_ros_control">
      <robotSimType>gazebo_ros_control/DefaultRobotHWSim</robotSimType>
      <legacyModeNS>true</legacyModeNS>
    </plugin>
  </gazebo>
</robot>
