<?xml version="1.0"?>
<!-- Revolute-Revolute Manipulator -->
<robot name="robotarm_5DOF" xmlns:xacro="http://www.ros.org/wiki/xacro">

 <!-- Import all Gazebo-customization elements, including Gazebo colors -->
  <xacro:include filename="$(find manipulator_h_description)/urdf/robotarm_5DOF.gazebo" />


 <!-- Used for fixing robot to Gazebo 'base_link' -->
 <link name="world">
  </link>

  <joint name="world" type="fixed">
    <origin xyz="0 0 0" rpy="0 0 0"/>
    <parent link="world"/>
    <child link="base_link"/>
  </joint>

  <link name="base_link">
    <inertial>
      <origin
        xyz="0 0 0.12" rpy="0 0 1.57" />
      <mass
        value="0.854996764620972" />
      <inertia
        ixx="0.00127367657233133"
        ixy="-9.78923195537527E-13"
        ixz="-2.93635909372344E-13"
        iyy="0.00127209146192002"
        iyz="1.73326120869336E-07"
        izz="0.000375253307095422" />
    </inertial>
    <visual>
      <origin
        xyz="0 0 0.12" rpy="0 0 1.57" />
      <geometry>
        <mesh
          filename="package://manipulator_h_description/meshes_5DOF/base_link.STL" />
      </geometry>
      <material
        name="">
        <color
          rgba="0.792156862745098 0.819607843137255 0.929411764705882 1" />
      </material>
    </visual>
    <collision>
      <origin
        xyz="0 0 0.12" rpy="0 0 1.57" />
      <geometry>
        <mesh
          filename="package://manipulator_h_description/meshes_5DOF/base_link.STL" />
      </geometry>
    </collision>
  </link>

	<joint name="joint1" type="revolute">
		<origin xyz="0 0 0.159" rpy="0 0 0" />
		<parent link="base_link" />
		<child link="link1" />
        <limit velocity="6.5" effort="1000" lower="-3.14" upper="3.14" />
        <dynamics damping="1"/>
		<axis xyz="0 0 1" />
	</joint>


  <transmission name="tran1">
    <type>transmission_interface/SimpleTransmission</type>
    <joint name="joint1">
      <hardwareInterface>EffortJointInterface</hardwareInterface>
    </joint>
    <actuator name="motor1">
      <hardwareInterface>EffortJointInterface</hardwareInterface>
      <mechanicalReduction>1</mechanicalReduction>
    </actuator>
  </transmission>

  <link
    name="link1">
    <inertial>
      <origin
        xyz="0 0 -0.039" rpy="3.14 0 0" />
      <mass
        value="0.933973833115025" />
      <inertia
        ixx="0.00130038494228848"
        ixy="-2.95844372439728E-13"
        ixz="-3.01467763831998E-11"
        iyy="0.000422142499355785"
        iyz="-1.73339894386112E-07"
        izz="0.0013123580996147" />
    </inertial>
    <visual>
      <origin
        xyz="0 0 -0.039" rpy="3.14 0 0" />
      <geometry>
        <mesh
          filename="package://manipulator_h_description/meshes_5DOF/link1.STL" />
      </geometry>
      <material
        name="">
        <color
          rgba="0.752941176470588 0.752941176470588 0.752941176470588 1" />
      </material>
    </visual>
    <collision>
      <origin
        xyz="0 0 -0.039" rpy="3.14 0 0" />
      <geometry>
        <mesh
          filename="package://manipulator_h_description/meshes_5DOF/link1.STL" />
      </geometry>
    </collision>
  </link>

	<joint name="joint2" type="revolute">
		<origin xyz="0 0 0" rpy="1.57 0 0" />
		<parent link="link1" />
		<child link="link2" />
		<axis xyz="0 0 1" />
        <limit velocity="6.5" effort="1000" lower="-3.14" upper="3.14" />
        <dynamics damping="1"/>
	</joint>


  <transmission name="tran2">
    <type>transmission_interface/SimpleTransmission</type>
    <joint name="joint2">
      <hardwareInterface>EffortJointInterface</hardwareInterface>
    </joint>
    <actuator name="motor2">
      <hardwareInterface>EffortJointInterface</hardwareInterface>
      <mechanicalReduction>1</mechanicalReduction>
    </actuator>
  </transmission>

  <link
    name="link2">
    <inertial>
      <origin
        xyz="0 0 0"
        rpy="0 0 0" />
      <mass
        value="2.17233482675649" />
      <inertia
        ixx="0.012588710454961"
        ixy="3.24699537352499E-11"
        ixz="-1.73376873509498E-07"
        iyy="0.00229782223136213"
        iyz="-2.39564649019806E-07"
        izz="0.0112510434237469" />
    </inertial>
    <visual>
      <origin
        xyz="0 0 0"
        rpy="0 0 0" />
      <geometry>
        <mesh
          filename="package://manipulator_h_description/meshes_5DOF/link2.STL" />
      </geometry>
      <material
        name="">
        <color
          rgba="0.752941176470588 0.752941176470588 0.752941176470588 1" />
      </material>
    </visual>
    <collision>
      <origin
        xyz="0 0 0"
        rpy="0 0 0" />
      <geometry>
        <mesh
          filename="package://manipulator_h_description/meshes_5DOF/link2.STL" />
      </geometry>
    </collision>
  </link>

	<joint name="joint3" type="revolute">
		<origin xyz="0 0.548 0" rpy="0 0 0" />
		<parent
		  link="link2" />
		<child
		  link="link3" />
		<axis
		  xyz="0 0 1" />
        <limit velocity="6.5" effort="1000" lower="-3.14" upper="3.14" />
        <dynamics damping="1"/>
	</joint>


  <transmission name="tran3">
    <type>transmission_interface/SimpleTransmission</type>
    <joint name="joint3">
      <hardwareInterface>EffortJointInterface</hardwareInterface>
    </joint>
    <actuator name="motor3">
      <hardwareInterface>EffortJointInterface</hardwareInterface>
      <mechanicalReduction>1</mechanicalReduction>
    </actuator>
  </transmission>

  <link
    name="link3">
    <inertial>
      <origin
        xyz="0 0 0"
        rpy="0 0 0" />
      <mass
        value="2.03963402194097" />
      <inertia
        ixx="0.0121595677954515"
        ixy="1.8895677510483E-12"
        ixz="1.26403080065892E-07"
        iyy="0.00186854119614137"
        iyz="-2.39564391781716E-07"
        izz="0.011185917848878" />
    </inertial>
    <visual>
      <origin
        xyz="0 0 0"
        rpy="0 0 0" />
      <geometry>
        <mesh
          filename="package://manipulator_h_description/meshes_5DOF/link3.STL" />
      </geometry>
      <material
        name="">
        <color
          rgba="0.752941176470588 0.752941176470588 0.752941176470588 1" />
      </material>
    </visual>
    <collision>
      <origin
        xyz="0 0 0"
        rpy="0 0 0" />
      <geometry>
        <mesh
          filename="package://manipulator_h_description/meshes_5DOF/link3.STL" />
      </geometry>
    </collision>
  </link>

	<joint name="joint4" type="revolute">
		<origin xyz="0 0.548 0" rpy="0 0 0" />
		<parent link="link3" />
		<child link="link4" />
		<axis xyz="0 0 1" />
        <limit velocity="6.5" effort="1000" lower="-3.14" upper="3.14" />
        <dynamics damping="0.7"/>
	</joint>


  <transmission name="tran4">
    <type>transmission_interface/SimpleTransmission</type>
    <joint name="joint4">
      <hardwareInterface>EffortJointInterface</hardwareInterface>
    </joint>
    <actuator name="motor4">
      <hardwareInterface>EffortJointInterface</hardwareInterface>
      <mechanicalReduction>1</mechanicalReduction>
    </actuator>
  </transmission>

  <link
    name="link4">
    <inertial>
      <origin
        xyz="-5.84108303602587E-11 0.093757042570968 0.000563667312071903"
        rpy="0 0 0" />
      <mass
        value="0.86104149872866" />
      <inertia ixx="1.0" ixy="0.0" ixz="0.0" iyy="1.0" iyz="0.0" izz="1.0" />
      <!---inertia
        ixx="0.000958719090443109"
        ixy="-6.78889479385674E-14"
        ixz="-1.92825748989735E-12"
        iyy="0.000454069680151404"
        iyz="-2.64915719473377E-07"
        izz="0.000905174777740181" /-->
    </inertial>
    <visual>
      <origin
        xyz="0 0 0"
        rpy="0 0 0" />
      <geometry>
        <mesh
          filename="package://manipulator_h_description/meshes_5DOF/link4.STL" />
      </geometry>
      <material
        name="">
        <color
          rgba="0.752941176470588 0.752941176470588 0.752941176470588 1" />
      </material>
    </visual>
    <collision>
      <origin
        xyz="0 0 0"
        rpy="0 0 0" />
      <geometry>
        <mesh
          filename="package://manipulator_h_description/meshes_5DOF/link4.STL" />
      </geometry>
    </collision>
  </link>

	<joint name="joint5" type="revolute">
		<origin xyz="0 0.159 0" rpy="0 0 0" />
		<parent link="link4" />
		<child link="end" />
		<axis xyz="0 1 0" />
        <limit velocity="6.5" effort="1000" lower="-3.14" upper="3.14" />
        <dynamics damping="0.7"/>
	</joint>


  <transmission name="tran5">
    <type>transmission_interface/SimpleTransmission</type>
    <joint name="joint5">
      <hardwareInterface>EffortJointInterface</hardwareInterface>
    </joint>
    <actuator name="motor5">
      <hardwareInterface>EffortJointInterface</hardwareInterface>
      <mechanicalReduction>1</mechanicalReduction>
    </actuator>
  </transmission>

  <link
    name="end">
    <inertial>
      <origin
        xyz="0 0.03 0"
        rpy="0 0 0" />
      <mass
        value="0.01" />
       <inertia ixx="1.0" ixy="0.0" ixz="0.0" iyy="1.0" iyz="0.0" izz="1.0" />
      <!--inertia
        ixx="0.000259199999999999"
        ixy="5.34084614707402E-19"
        ixz="-9.20138409382816E-20"
        iyy="0.000648"
        iyz="4.45440999867654E-20"
        izz="0.000647999999999999" /-->
    </inertial>
    <visual>
      <origin
        xyz="0 0.06 0"
        rpy="0 0 0" />
      <geometry>
        <mesh
          filename="package://manipulator_h_description/meshes_5DOF/end.STL" />
      </geometry>
      <material
        name="">
        <color
          rgba="0.792156862745098 0.819607843137255 0.933333333333333 1" />
      </material>
    </visual>
    <collision>
      <origin
        xyz="0 0.06 0"
        rpy="0 0 0" />
      <geometry>
        <mesh
          filename="package://manipulator_h_description/meshes_5DOF/end.STL" />
      </geometry>
    </collision>
  </link>


  <link name="wall">
     <inertial>
       <origin xyz="-0.15 0 0" rpy="0 0 0"/>
       <mass value="1000"/>
       <inertia ixx="100"  ixy="0"  ixz="0" iyy="100" iyz="0" izz="100" />
     </inertial>

     <visual>
       <origin xyz="-0.15 0 0" rpy="0 0 0" />
      <geometry>
        <box size="0.1 2 2" />
      </geometry>
      <material name="Cyan">
        <color rgba="0 1.0 1.0 1.0"/>
      </material>
    </visual>

    <collision>
      <origin xyz="-0.15 0 0" rpy="0 0 0"/>
      <geometry>
        <box size="0.1 2 2" />
      </geometry>
    </collision>
 </link>

 <joint name="wall_joint" type="fixed">
   <parent link="world"/>
   <child link="wall"/>
   <origin xyz="-0.15 0 1"/>
 </joint>

 <link name="floor">
    <inertial>
      <origin xyz="0 0 0.001" rpy="0 0 0"/>
      <mass value="1000"/>
      <inertia ixx="1"  ixy="0"  ixz="0" iyy="1" iyz="0" izz="1" />
    </inertial>

    <visual>
      <origin xyz="0 0 0.001" rpy="0 0 0" />
     <geometry>
       <box size="2 2 0.001" />
     </geometry>
     <material name="Cyan">
       <color rgba="0 1.0 1.0 1.0"/>
     </material>
   </visual>

   <collision>
     <origin xyz="0 0 0.001" rpy="0 0 0"/>
     <geometry>
       <box size="2 2 0.001" />
     </geometry>
   </collision>
</link>

<joint name="floor_joint" type="fixed">
  <parent link="world"/>
  <child link="floor"/>
  <origin xyz="0.7 0 0.005"/>
</joint>

 <gazebo>
    <plugin name="gazebo_ros_control" filename="libgazebo_ros_control.so">
      <robotSimType>gazebo_ros_control/DefaultRobotHWSim</robotSimType>
      <legacyModeNS>true</legacyModeNS>
    </plugin>
  </gazebo>


</robot>
